<sdf version='1.4'>
  <model name='jaco'>
    <link name='base_link'>
      <pose>0 0 0 0 -0 0</pose>
      <inertial>
        <pose>0 0 0 0 -0 0</pose>
        <mass>0.752103</mass>
        <inertia>
          <ixx>0.009025</ixx>
          <ixy>-2e-06</ixy>
          <ixz>-5e-06</ixz>
          <iyy>0.009007</iyy>
          <iyz>0</iyz>
          <izz>0.000704</izz>
        </inertia>
      </inertial>
      <collision name='base_link_collision'>
        <pose>0 0 0 0 -0 0</pose>
        <geometry>
          <mesh>
            <scale>1 1 1</scale>
            <uri>model://kinova_description/meshes/jaco/collision/base.stl</uri>
          </mesh>
        </geometry>
      </collision>
      <visual name='base_link_visual'>
        <pose>0 0 0 0 -0 0</pose>
        <geometry>
          <mesh>
            <scale>1 1 1</scale>
            <uri>model://kinova_description/meshes/jaco/visual/base.dae</uri>
          </mesh>
        </geometry>
      </visual>
      <velocity_decay>
        <linear>0</linear>
        <angular>0</angular>
      </velocity_decay>
    </link>
    <joint name='world_joint' type='revolute'>
      <child>base_link</child>
      <parent>world</parent>
      <axis>
        <limit>
          <lower>0</lower>
          <upper>0</upper>
        </limit>
        <dynamics>
          <damping>0</damping>
        </dynamics>
        <xyz>0 0 1</xyz>
      </axis>
    </joint>
    <link name='shoulder_link'>
      <pose>0 0 0.15675 0 -0 0</pose>
      <inertial>
        <pose>0 0 0 0 -0 0</pose>
        <mass>0.839784</mass>
        <inertia>
          <ixx>0.005735</ixx>
          <ixy>0</ixy>
          <ixz>0</ixz>
          <iyy>0.005801</iyy>
          <iyz>0.000496</iyz>
          <izz>0.00057</izz>
        </inertia>
      </inertial>
      <collision name='shoulder_link_collision'>
        <pose>0 0 0 0 -0 0</pose>
        <geometry>
          <mesh>
            <scale>1 1 1</scale>
            <uri>model://kinova_description/meshes/jaco/collision/shoulder.stl</uri>
          </mesh>
        </geometry>
      </collision>
      <visual name='shoulder_link_visual'>
        <pose>0 0 0 0 -0 0</pose>
        <geometry>
          <mesh>
            <scale>1 1 1</scale>
            <uri>model://kinova_description/meshes/jaco/visual/shoulder.dae</uri>
          </mesh>
        </geometry>
      </visual>
      <velocity_decay>
        <linear>0</linear>
        <angular>0</angular>
      </velocity_decay>
    </link>
    <joint name='shoulder_pan_joint' type='revolute'>
      <child>shoulder_link</child>
      <parent>base_link</parent>
      <axis>
        <xyz>0 0 1</xyz>
        <limit>
          <lower>-1e+16</lower>
          <upper>1e+16</upper>
        </limit>
        <dynamics>
          <damping>0</damping>
        </dynamics>
      </axis>
    </joint>
    <link name='upper_arm_link'>
      <pose>0 0 0.2755 -2.65359e-06 -1.57079 3.14159</pose>
      <inertial>
        <pose>0 0 0 0 -0 0</pose>
        <mass>0.968862</mass>
        <inertia>
          <ixx>0.000789</ixx>
          <ixy>8e-06</ixy>
          <ixz>-0.002914</ixz>
          <iyy>0.069034</iyy>
          <iyz>-1e-06</iyz>
          <izz>0.069005</izz>
        </inertia>
      </inertial>
      <collision name='upper_arm_link_collision'>
        <pose>0 0 0 0 -0 0</pose>
        <geometry>
          <mesh>
            <scale>1 1 1</scale>
            <uri>model://kinova_description/meshes/jaco/collision/upper_arm.stl</uri>
          </mesh>
        </geometry>
      </collision>
      <visual name='upper_arm_link_visual'>
        <pose>0 0 0 0 -0 0</pose>
        <geometry>
          <mesh>
            <scale>1 1 1</scale>
            <uri>model://kinova_description/meshes/jaco/visual/upper_arm.dae</uri>
          </mesh>
        </geometry>
      </visual>
      <velocity_decay>
        <linear>0</linear>
        <angular>0</angular>
      </velocity_decay>
    </link>
    <joint name='shoulder_lift_joint' type='revolute'>
      <child>upper_arm_link</child>
      <parent>shoulder_link</parent>
      <axis>
        <xyz>1 -3.58979e-09 -1.7949e-09</xyz>
        <limit>
          <lower>-2.356</lower>
          <upper>2.356</upper>
          <effort>30.5</effort>
          <velocity>1</velocity>
        </limit>
        <dynamics>
          <damping>0</damping>
        </dynamics>
      </axis>
    </joint>
    <link name='forearm_link'>
      <pose>0.00975 -3.50005e-11 0.6855 -2.65359e-06 -1.57079 3.14159</pose>
      <inertial>
        <pose>0 0 0 0 -0 0</pose>
        <mass>0.70996</mass>
        <inertia>
          <ixx>0.000341</ixx>
          <ixy>3e-06</ixy>
          <ixz>-3.4e-05</ixz>
          <iyy>0.008491</iyy>
          <iyz>-0</iyz>
          <izz>0.008612</izz>
        </inertia>
      </inertial>
      <collision name='forearm_link_collision'>
        <pose>0 0 0 0 -0 0</pose>
        <geometry>
          <mesh>
            <scale>1 1 1</scale>
            <uri>model://kinova_description/meshes/jaco/collision/forearm.stl</uri>
          </mesh>
        </geometry>
      </collision>
      <visual name='forearm_link_visual'>
        <pose>0 0 0 0 -0 0</pose>
        <geometry>
          <mesh>
            <scale>1 1 1</scale>
            <uri>model://kinova_description/meshes/jaco/visual/forearm.dae</uri>
          </mesh>
        </geometry>
      </visual>
      <velocity_decay>
        <linear>0</linear>
        <angular>0</angular>
      </velocity_decay>
    </link>
    <joint name='elbow_joint' type='revolute'>
      <child>forearm_link</child>
      <parent>upper_arm_link</parent>
      <axis>
        <xyz>1 -3.58979e-09 -1.7949e-09</xyz>
        <limit>
          <lower>-2.862</lower>
          <upper>2.862</upper>
          <effort>18</effort>
          <velocity>0.75</velocity>
        </limit>
        <dynamics>
          <damping>0</damping>
        </dynamics>
      </axis>
    </joint>
    <link name='wrist_1_link'>
      <pose>0.00975 -3.50005e-11 0.89275 -3.58979e-09 3.58979e-09 -3.58979e-09</pose>
      <inertial>
        <pose>0 0 0 0 -0 0</pose>
        <mass>0.441232</mass>
        <inertia>
          <ixx>0.000924</ixx>
          <ixy>0</ixy>
          <ixz>-0.000294</ixz>
          <iyy>0.001034</iyy>
          <iyz>0</iyz>
          <izz>0.000312</izz>
        </inertia>
      </inertial>
      <collision name='wrist_1_link_collision'>
        <pose>0 0 0 0 -0 0</pose>
        <geometry>
          <mesh>
            <scale>1 1 1</scale>
            <uri>model://kinova_description/meshes/jaco/collision/wrist_1.stl</uri>
          </mesh>
        </geometry>
      </collision>
      <visual name='wrist_1_link_visual'>
        <pose>0 0 0 0 -0 0</pose>
        <geometry>
          <mesh>
            <scale>1 1 1</scale>
            <uri>model://kinova_description/meshes/jaco/visual/wrist_1.dae</uri>
          </mesh>
        </geometry>
      </visual>
      <velocity_decay>
        <linear>0</linear>
        <angular>0</angular>
      </velocity_decay>
    </link>
    <joint name='wrist_1_joint' type='revolute'>
      <child>wrist_1_link</child>
      <parent>forearm_link</parent>
      <axis>
        <xyz>3.58979e-09 3.58979e-09 1</xyz>
        <limit>
          <lower>-1e+16</lower>
          <upper>1e+16</upper>
        </limit>
        <dynamics>
          <damping>0</damping>
        </dynamics>
      </axis>
    </joint>
    <link name='wrist_2_link'>
      <pose>0.00975 1.18488e-10 0.935507 -7.17959e-09 1.0472 -9.8075e-09</pose>
      <inertial>
        <pose>0 0 0 0 -0 0</pose>
        <mass>0.441232</mass>
        <inertia>
          <ixx>0.003063</ixx>
          <ixy>0</ixy>
          <ixz>-0.000522</ixz>
          <iyy>0.003174</iyy>
          <iyz>-1e-06</iyz>
          <izz>0.000312</izz>
        </inertia>
      </inertial>
      <collision name='wrist_2_link_collision'>
        <pose>0 0 0 0 -0 0</pose>
        <geometry>
          <mesh>
            <scale>1 1 1</scale>
            <uri>model://kinova_description/meshes/jaco/collision/wrist_2.stl</uri>
          </mesh>
        </geometry>
      </collision>
      <visual name='wrist_2_link_visual'>
        <pose>0 0 0 0 -0 0</pose>
        <geometry>
          <mesh>
            <scale>1 1 1</scale>
            <uri>model://kinova_description/meshes/jaco/visual/wrist_2.dae</uri>
          </mesh>
        </geometry>
      </visual>
      <velocity_decay>
        <linear>0</linear>
        <angular>0</angular>
      </velocity_decay>
    </link>
    <joint name='wrist_2_joint' type='revolute'>
      <child>wrist_2_link</child>
      <parent>wrist_1_link</parent>
      <axis>
        <xyz>0.866025 -1.31396e-09 0.5</xyz>
        <limit>
          <lower>-1e+16</lower>
          <upper>1e+16</upper>
        </limit>
        <dynamics>
          <damping>0</damping>
        </dynamics>
      </axis>
    </joint>
    <link name='wrist_3_link'>
      <pose>0.0838074 6.12675e-12 0.978264 -3.58979e-09 3.58979e-09 -3.58979e-09</pose>
      <inertial>
        <pose>0 0 0.0597616 0 -0 0</pose>
        <mass>1.00024</mass>
        <inertia>
          <ixx>0.00505549</ixx>
          <ixy>6.49957e-21</ixy>
          <ixz>-4.46996e-20</ixz>
          <iyy>0.00511549</iyy>
          <iyz>-2.99591e-27</iyz>
          <izz>0.000589</izz>
        </inertia>
      </inertial>
      <collision name='wrist_3_link_collision'>
        <pose>0 0 0 0 -0 0</pose>
        <geometry>
          <mesh>
            <scale>1 1 1</scale>
            <uri>model://kinova_description/meshes/jaco/collision/wrist_3.stl</uri>
          </mesh>
        </geometry>
      </collision>
      <collision name='wrist_3_link_collision_robotiq_85_base_link'>
        <pose>0 0 0.093847 1.57079 -1.57079 -3.14159</pose>
        <geometry>
          <mesh>
            <scale>1 1 1</scale>
            <uri>model://kinova_description/meshes/robotiq_85_gripper/collision/robotiq_85_base_link.stl</uri>
          </mesh>
        </geometry>
      </collision>
      <visual name='wrist_3_link_visual'>
        <pose>0 0 0 0 -0 0</pose>
        <geometry>
          <mesh>
            <scale>1 1 1</scale>
            <uri>model://kinova_description/meshes/jaco/visual/wrist_3.dae</uri>
          </mesh>
        </geometry>
      </visual>
      <visual name='wrist_3_link_visual_robotiq_85_base_link'>
        <pose>0 0 0.093847 1.57079 -1.57079 -3.14159</pose>
        <geometry>
          <mesh>
            <scale>1 1 1</scale>
            <uri>model://kinova_description/meshes/robotiq_85_gripper/visual/robotiq_85_base_link.dae</uri>
          </mesh>
        </geometry>
      </visual>
      <velocity_decay>
        <linear>0</linear>
        <angular>0</angular>
      </velocity_decay>
    </link>
    <joint name='wrist_3_joint' type='revolute'>
      <child>wrist_3_link</child>
      <parent>wrist_2_link</parent>
      <axis>
        <xyz>3.58979e-09 3.58979e-09 1</xyz>
        <limit>
          <lower>-1e+16</lower>
          <upper>1e+16</upper>
        </limit>
        <dynamics>
          <damping>0</damping>
        </dynamics>
      </axis>
    </joint>
    <link name='robotiq_85_left_inner_knuckle_link'>
      <pose>0.0965074 5.40708e-10 1.13353 -2.1588 -1.57079 -2.55359</pose>
      <inertial>
        <pose>0 0 0 0 -0 0</pose>
        <mass>0.029951</mass>
        <inertia>
          <ixx>3.9e-05</ixx>
          <ixy>0</ixy>
          <ixz>0</ixz>
          <iyy>5e-06</iyy>
          <iyz>0</iyz>
          <izz>3.5e-05</izz>
        </inertia>
      </inertial>
      <collision name='robotiq_85_left_inner_knuckle_link_collision'>
        <pose>0 0 0 0 -0 0</pose>
        <geometry>
          <mesh>
            <scale>1 1 1</scale>
            <uri>model://kinova_description/meshes/robotiq_85_gripper/collision/robotiq_85_inner_knuckle_link.stl</uri>
          </mesh>
        </geometry>
      </collision>
      <visual name='robotiq_85_left_inner_knuckle_link_visual'>
        <pose>0 0 0 0 -0 0</pose>
        <geometry>
          <mesh>
            <scale>1 1 1</scale>
            <uri>model://kinova_description/meshes/robotiq_85_gripper/visual/robotiq_85_inner_knuckle_link.dae</uri>
          </mesh>
        </geometry>
      </visual>
      <velocity_decay>
        <linear>0</linear>
        <angular>0</angular>
      </velocity_decay>
    </link>
    <joint name='robotiq_85_left_inner_knuckle_joint' type='revolute'>
      <child>robotiq_85_left_inner_knuckle_link</child>
      <parent>wrist_3_link</parent>
      <axis>
        <xyz>-5.38469e-09 -1 3.58979e-09</xyz>
        <limit>
          <lower>-0.804</lower>
          <upper>0</upper>
          <effort>1000</effort>
          <velocity>2</velocity>
        </limit>
        <dynamics/>
      </axis>
    </joint>
    <link name='robotiq_85_left_finger_tip_link'>
      <pose>0.134107 4.9275e-10 1.17657 -2.1588 -1.57079 -2.55359</pose>
      <inertial>
        <pose>0 0 0 0 -0 0</pose>
        <mass>0.019555</mass>
        <inertia>
          <ixx>2e-06</ixx>
          <ixy>0</ixy>
          <ixz>0</ixz>
          <iyy>5e-06</iyy>
          <iyz>0</iyz>
          <izz>6e-06</izz>
        </inertia>
      </inertial>
      <collision name='robotiq_85_left_finger_tip_link_collision'>
        <pose>0 0 0 0 -0 0</pose>
        <geometry>
          <mesh>
            <scale>1 1 1</scale>
            <uri>model://kinova_description/meshes/robotiq_85_gripper/collision/robotiq_85_finger_tip_link.stl</uri>
          </mesh>
        </geometry>
      </collision>
      <visual name='robotiq_85_left_finger_tip_link_visual'>
        <pose>0 0 0 0 -0 0</pose>
        <geometry>
          <mesh>
            <scale>1 1 1</scale>
            <uri>model://kinova_description/meshes/robotiq_85_gripper/visual/robotiq_85_finger_tip_link.dae</uri>
          </mesh>
        </geometry>
      </visual>
      <velocity_decay>
        <linear>0</linear>
        <angular>0</angular>
      </velocity_decay>
    </link>
    <joint name='robotiq_85_left_finger_tip_joint' type='revolute'>
      <child>robotiq_85_left_finger_tip_link</child>
      <parent>robotiq_85_left_inner_knuckle_link</parent>
      <axis>
        <xyz>-5.38469e-09 -1 3.58979e-09</xyz>
        <limit>
          <lower>0</lower>
          <upper>1.5707</upper>
          <effort>1000</effort>
          <velocity>2</velocity>
        </limit>
        <dynamics/>
      </axis>
    </joint>
    <link name='robotiq_85_left_knuckle_link'>
      <pose>0.114409 4.85188e-10 1.12702 -2.1588 -1.57079 -2.55359</pose>
      <inertial>
        <pose>-0.00243606 -0.0187741 0 0 -0 0</pose>
        <mass>0.0458</mass>
        <inertia>
          <ixx>2.29304e-05</ixx>
          <ixy>-4.4183e-06</ixy>
          <ixz>0</ixz>
          <iyy>2.2184e-05</iyy>
          <iyz>0</iyz>
          <izz>4.11145e-05</izz>
        </inertia>
      </inertial>
      <collision name='robotiq_85_left_knuckle_link_collision'>
        <pose>0 0 0 0 -0 0</pose>
        <geometry>
          <mesh>
            <scale>1 1 1</scale>
            <uri>model://kinova_description/meshes/robotiq_85_gripper/collision/robotiq_85_knuckle_link.stl</uri>
          </mesh>
        </geometry>
      </collision>
      <collision name='robotiq_85_left_knuckle_link_collision_robotiq_85_left_finger_link'>
        <pose>-0.00408552 -0.031486 0 0 -0 0</pose>
        <geometry>
          <mesh>
            <scale>1 1 1</scale>
            <uri>model://kinova_description/meshes/robotiq_85_gripper/collision/robotiq_85_finger_link.stl</uri>
          </mesh>
        </geometry>
      </collision>
      <visual name='robotiq_85_left_knuckle_link_visual'>
        <pose>0 0 0 0 -0 0</pose>
        <geometry>
          <mesh>
            <scale>1 1 1</scale>
            <uri>model://kinova_description/meshes/robotiq_85_gripper/visual/robotiq_85_knuckle_link.dae</uri>
          </mesh>
        </geometry>
      </visual>
      <visual name='robotiq_85_left_knuckle_link_visual_robotiq_85_left_finger_link'>
        <pose>-0.00408552 -0.031486 0 0 -0 0</pose>
        <geometry>
          <mesh>
            <scale>1 1 1</scale>
            <uri>model://kinova_description/meshes/robotiq_85_gripper/visual/robotiq_85_finger_link.dae</uri>
          </mesh>
        </geometry>
      </visual>
      <velocity_decay>
        <linear>0</linear>
        <angular>0</angular>
      </velocity_decay>
    </link>
    <joint name='robotiq_85_left_knuckle_joint' type='revolute'>
      <child>robotiq_85_left_knuckle_link</child>
      <parent>wrist_3_link</parent>
      <axis>
        <xyz>-5.38469e-09 -1 3.58979e-09</xyz>
        <limit>
          <lower>0</lower>
          <upper>0.804</upper>
          <effort>1000</effort>
          <velocity>2</velocity>
        </limit>
        <dynamics/>
      </axis>
    </joint>
    <link name='robotiq_85_right_inner_knuckle_link'>
      <pose>0.0711074 5.86298e-10 1.13353 0.982793 -1.57079 -2.55359</pose>
      <inertial>
        <pose>0 0 0 0 -0 0</pose>
        <mass>0.029951</mass>
        <inertia>
          <ixx>3.9e-05</ixx>
          <ixy>0</ixy>
          <ixz>0</ixz>
          <iyy>5e-06</iyy>
          <iyz>0</iyz>
          <izz>3.5e-05</izz>
        </inertia>
      </inertial>
      <collision name='robotiq_85_right_inner_knuckle_link_collision'>
        <pose>0 0 0 0 -0 0</pose>
        <geometry>
          <mesh>
            <scale>1 1 1</scale>
            <uri>model://kinova_description/meshes/robotiq_85_gripper/collision/robotiq_85_inner_knuckle_link.stl</uri>
          </mesh>
        </geometry>
      </collision>
      <visual name='robotiq_85_right_inner_knuckle_link_visual'>
        <pose>0 0 0 0 -0 0</pose>
        <geometry>
          <mesh>
            <scale>1 1 1</scale>
            <uri>model://kinova_description/meshes/robotiq_85_gripper/visual/robotiq_85_inner_knuckle_link.dae</uri>
          </mesh>
        </geometry>
      </visual>
      <velocity_decay>
        <linear>0</linear>
        <angular>0</angular>
      </velocity_decay>
    </link>
    <joint name='robotiq_85_right_inner_knuckle_joint' type='revolute'>
      <child>robotiq_85_right_inner_knuckle_link</child>
      <parent>wrist_3_link</parent>
      <axis>
        <xyz>1.7949e-09 1 -3.58979e-09</xyz>
        <limit>
          <lower>0</lower>
          <upper>0.804</upper>
          <effort>1000</effort>
          <velocity>2</velocity>
        </limit>
        <dynamics/>
      </axis>
    </joint>
    <link name='robotiq_85_right_finger_tip_link'>
      <pose>0.033508 8.08289e-10 1.17657 0.982793 -1.57079 -2.55359</pose>
      <inertial>
        <pose>0 0 0 0 -0 0</pose>
        <mass>0.019555</mass>
        <inertia>
          <ixx>2e-06</ixx>
          <ixy>0</ixy>
          <ixz>0</ixz>
          <iyy>5e-06</iyy>
          <iyz>0</iyz>
          <izz>6e-06</izz>
        </inertia>
      </inertial>
      <collision name='robotiq_85_right_finger_tip_link_collision'>
        <pose>0 0 0 0 -0 0</pose>
        <geometry>
          <mesh>
            <scale>1 1 1</scale>
            <uri>model://kinova_description/meshes/robotiq_85_gripper/collision/robotiq_85_finger_tip_link.stl</uri>
          </mesh>
        </geometry>
      </collision>
      <visual name='robotiq_85_right_finger_tip_link_visual'>
        <pose>0 0 0 0 -0 0</pose>
        <geometry>
          <mesh>
            <scale>1 1 1</scale>
            <uri>model://kinova_description/meshes/robotiq_85_gripper/visual/robotiq_85_finger_tip_link.dae</uri>
          </mesh>
        </geometry>
      </visual>
      <velocity_decay>
        <linear>0</linear>
        <angular>0</angular>
      </velocity_decay>
    </link>
    <joint name='robotiq_85_right_finger_tip_joint' type='revolute'>
      <child>robotiq_85_right_finger_tip_link</child>
      <parent>robotiq_85_right_inner_knuckle_link</parent>
      <axis>
        <xyz>1.7949e-09 1 -3.58979e-09</xyz>
        <limit>
          <lower>0</lower>
          <upper>1.5707</upper>
          <effort>1000</effort>
          <velocity>2</velocity>
        </limit>
        <dynamics/>
      </axis>
    </joint>
    <link name='robotiq_85_right_knuckle_link'>
      <pose>0.0532062 5.9504e-10 1.12702 0.982793 -1.57079 -2.55359</pose>
      <inertial>
        <pose>-0.00243606 -0.0187741 0 0 -0 0</pose>
        <mass>0.0458</mass>
        <inertia>
          <ixx>2.29304e-05</ixx>
          <ixy>-4.4183e-06</ixy>
          <ixz>0</ixz>
          <iyy>2.2184e-05</iyy>
          <iyz>0</iyz>
          <izz>4.11145e-05</izz>
        </inertia>
      </inertial>
      <collision name='robotiq_85_right_knuckle_link_collision'>
        <pose>0 0 0 0 -0 0</pose>
        <geometry>
          <mesh>
            <scale>1 1 1</scale>
            <uri>model://kinova_description/meshes/robotiq_85_gripper/collision/robotiq_85_knuckle_link.stl</uri>
          </mesh>
        </geometry>
      </collision>
      <collision name='robotiq_85_right_knuckle_link_collision_robotiq_85_right_finger_link'>
        <pose>-0.00408552 -0.031486 0 0 -0 0</pose>
        <geometry>
          <mesh>
            <scale>1 1 1</scale>
            <uri>model://kinova_description/meshes/robotiq_85_gripper/collision/robotiq_85_finger_link.stl</uri>
          </mesh>
        </geometry>
      </collision>
      <visual name='robotiq_85_right_knuckle_link_visual'>
        <pose>0 0 0 0 -0 0</pose>
        <geometry>
          <mesh>
            <scale>1 1 1</scale>
            <uri>model://kinova_description/meshes/robotiq_85_gripper/visual/robotiq_85_knuckle_link.dae</uri>
          </mesh>
        </geometry>
      </visual>
      <visual name='robotiq_85_right_knuckle_link_visual_robotiq_85_right_finger_link'>
        <pose>-0.00408552 -0.031486 0 0 -0 0</pose>
        <geometry>
          <mesh>
            <scale>1 1 1</scale>
            <uri>model://kinova_description/meshes/robotiq_85_gripper/visual/robotiq_85_finger_link.dae</uri>
          </mesh>
        </geometry>
      </visual>
      <velocity_decay>
        <linear>0</linear>
        <angular>0</angular>
      </velocity_decay>
    </link>
    <joint name='robotiq_85_right_knuckle_joint' type='revolute'>
      <child>robotiq_85_right_knuckle_link</child>
      <parent>wrist_3_link</parent>
      <axis>
        <xyz>1.7949e-09 1 -3.58979e-09</xyz>
        <limit>
          <lower>-0.804</lower>
          <upper>0</upper>
          <effort>1000</effort>
          <velocity>2</velocity>
        </limit>
        <dynamics/>
      </axis>
    </joint>
    <plugin name='robotiq_85_right_knuckle_joint_mimic' filename='libroboticsgroup_gazebo_mimic_joint_plugin.so'>
      <joint>robotiq_85_left_knuckle_joint</joint>
      <mimicJoint>robotiq_85_right_knuckle_joint</mimicJoint>
    </plugin>
    <plugin name='robotiq_85_right_knuckle_link' filename='libroboticsgroup_gazebo_disable_link_plugin.so'>
      <link>robotiq_85_right_knuckle_link</link>
    </plugin>
    <plugin name='robotiq_85_left_inner_knuckle_joint_mimic' filename='libroboticsgroup_gazebo_mimic_joint_plugin.so'>
      <joint>robotiq_85_left_knuckle_joint</joint>
      <mimicJoint>robotiq_85_left_inner_knuckle_joint</mimicJoint>
    </plugin>
    <plugin name='robotiq_85_left_inner_knuckle_link' filename='libroboticsgroup_gazebo_disable_link_plugin.so'>
      <link>robotiq_85_left_inner_knuckle_link</link>
    </plugin>
    <plugin name='robotiq_85_right_inner_knuckle_joint_mimic' filename='libroboticsgroup_gazebo_mimic_joint_plugin.so'>
      <joint>robotiq_85_left_knuckle_joint</joint>
      <mimicJoint>robotiq_85_right_inner_knuckle_joint</mimicJoint>
    </plugin>
    <plugin name='robotiq_85_right_inner_knuckle_link' filename='libroboticsgroup_gazebo_disable_link_plugin.so'>
      <link>robotiq_85_right_inner_knuckle_link</link>
    </plugin>
    <plugin name='robotiq_85_left_finger_tip_joint_mimic' filename='libroboticsgroup_gazebo_mimic_joint_plugin.so'>
      <joint>robotiq_85_left_knuckle_joint</joint>
      <mimicJoint>robotiq_85_left_finger_tip_joint</mimicJoint>
      <multiplier>-1</multiplier>
    </plugin>
    <plugin name='robotiq_85_left_finger_tip_link' filename='libroboticsgroup_gazebo_disable_link_plugin.so'>
      <link>robotiq_85_left_finger_tip_link</link>
    </plugin>
    <static>0</static>
    <plugin name='robotiq_85_right_finger_tip_joint_mimic' filename='libroboticsgroup_gazebo_mimic_joint_plugin.so'>
      <joint>robotiq_85_left_knuckle_joint</joint>
      <mimicJoint>robotiq_85_right_finger_tip_joint</mimicJoint>
      <multiplier>-1</multiplier>
    </plugin>
    <plugin name='robotiq_85_right_finger_tip_link' filename='libroboticsgroup_gazebo_disable_link_plugin.so'>
      <link>robotiq_85_right_finger_tip_link</link>
    </plugin>
  </model>
</sdf>
